第18章 错误处理

[TOC]

##1 表示和抛出错误
在 Swift 中，错误表示为遵循 Error协议类型的值。这个空的协议明确了一个类型可以用于错误处理。

Swift 枚举是典型的为一组相关错误条件建模的完美配适类型，关联值还允许错误错误通讯携带额外的信息。比如说，这是你可能会想到的游戏里自动售货机会遇到的错误条件：
```
enum VendingMachineError: Error {
    case invalidSelection
    case insufficientFunds(coinsNeeded: Int)
    case outOfStock
}
``` 
抛出一个错误允许你明确某些意外的事情发生了并且正常的执行流不能继续下去。你可以使用 throw 语句来抛出一个错误。比如说，下面的代码通过抛出一个错误来明确自动售货机需要五个额外的金币：
```
throw VendingMachineError.insufficientFunds(coinsNeeded: 5)
```

##2 处理错误
在 Swift 中有四种方式来处理错误。你可以将来自函数的错误传递给调用函数的代码中，使用 do-catch 语句来处理错误，把错误作为可选项的值，或者错误不会发生的断言。

当函数抛出一个错误，它就改变了你程序的流，所以能够快速定位错误就显得格外重要。要定位你代码中的这些位置，使用 try 关键字——或者 try? 或 try! 变体——放在调用函数、方法或者会抛出错误的初始化器代码之前。

Swift 中的错误处理， try, catch  和 throw 的使用与其他语言中的异常处理很相仿。不同于许多语言中的异常处理——包括 Objective-C ——Swift 中的错误处理并不涉及调用堆栈展开，一个高占用过程。因此， throw 语句的性能特征与 return 比不差多少。

###2.1 使用抛出函数传递错误
为了明确一个函数或者方法可以抛出错误，你要在它的声明当中的形式参数后边写上 throws关键字。使用 throws标记的函数叫做抛出函数。如果它明确了一个返回类型，那么 throws关键字要在返回箭头 ( ->)之前。
```
func canThrowErrors() throws -> String
 
func cannotThrowErrors() -> String
```
 抛出函数可以把它内部抛出的错误传递到它被调用的生效范围之内。
 
 只有抛出函数可以传递错误。任何在非抛出函数中抛出的错误都必须在该函数内部处理。
 
 ```
 struct Item {
    var price: Int
    var count: Int
}
 
class VendingMachine {
    var inventory = [
        "Candy Bar": Item(price: 12, count: 7),
        "Chips": Item(price: 10, count: 4),
        "Pretzels": Item(price: 7, count: 11)
    ]
    var coinsDeposited = 0
    
    func vend(itemNamed name: String) throws {
        guard let item = inventory[name] else {
            throw VendingMachineError.invalidSelection
        }
        
        guard item.count > 0 else {
            throw VendingMachineError.outOfStock
        }
        
        guard item.price <= coinsDeposited else {
            throw VendingMachineError.insufficientFunds(coinsNeeded: item.price - coinsDeposited)
        }
        
        coinsDeposited -= item.price
        
        var newItem = item
        newItem.count -= 1
        inventory[name] = newItem
        
        print("Dispensing \(name)")
    }
}
 ```
 可抛出的初始化器可以像可抛出函数那样传递错误。
 ```
 struct PurchasedSnack {
    let name: String
    init(name: String, vendingMachine: VendingMachine) throws {
        try vendingMachine.vend(itemNamed: name)
        self.name = name
    }
}
 ```
###2.2 使用 Do-Catch 处理错误
使用 do-catch语句来通过运行一段代码处理错误。如果do分句中抛出了一个错误，它就会与 catch分句匹配，以确定其中之一可以处理错误。
这是 do-catch语句的通常使用姿势：
```
do {
    try expression
    statements
} catch pattern 1 {
    statements
} catch pattern 2 where condition {
    statements
}
```
在 catch后写一个模式来明确分句可以处理哪个错误。如果一个 catch分句没有模式，这个分句就可以匹配所有错误并且绑定这个错误到本地常量 error上。

如果抛出错误，执行会立即切换到 catch分句，它决定是否传递来继续。如果没有错误抛出， do语句中剩下的语句将会被执行。

catch分句没有必要处理 do分句可能抛出的所有错误。如果没有 catch分句能处理这个错误，那错误就会传递到周围的生效范围当中。总之，错误必须得在周围某个范围内得到处理。

在不抛出错误的函数中， do-catch 分句就必须处理错误。在可抛出函数中，要么 do-catch 分句处理错误，要么调用者处理。如果错误被传递到了顶层生效范围但还是没有被处理，你就会得到一个运行时错误了。


###2.3 转换错误为可选项

使用 try?通过将错误转换为可选项来处理一个错误。如果一个错误在 try?表达式中抛出，则表达式的值为 nil。比如说下面的代码x和y拥有同样的值和行为：

```
func someThrowingFunction() throws -> Int {
    // ...
}
 
let x = try? someThrowingFunction()
 
let y: Int?
do {
    y = try someThrowingFunction()
} catch {
    y = nil
}
```
当你想要在同一句里处理所有错误时，使用 try?能让你的错误处理代码更加简洁。比如，下边的代码使用了一些方法来获取数据，或者在所有方式都失败后返回 nil。
```
func fetchData() -> Data? {
    if let data = try? fetchDataFromDisk() { return data }
    if let data = try? fetchDataFromServer() { return data }
    return nil
}
```
###2.4 取消错误传递
事实上有时你已经知道一个抛出错误或者方法不会在运行时抛出错误。在这种情况下，你可以在表达式前写 try!来取消错误传递并且把调用放进不会有错误抛出的运行时断言当中。如果错误真的抛出了，你会得到一个运行时错误。

```
let photo = try! loadImage("./Resources/John Appleseed.jpg")
```
##3 指定清理操作
使用 defer语句来在代码离开当前代码块前执行语句合集。这个语句允许你在以任何方式离开当前代码块前执行必须要的清理工作——无论是因为抛出了错误还是因为 return或者 break这样的语句。比如，你可以使用 defer语句来保证文件描述符都关闭并且手动指定的内存到被释放。

defer语句延迟执行直到当前范围退出。这个语句由 defer关键字和需要稍后执行的语句组成。被延迟执行的语句可能不会包含任何会将控制转出语句的代码，比如 break或 return语句，或者通过抛出一个错误。延迟的操作与其在代码中书写的顺序相反执行——就是说，第一个 defer语句中的代码会在第二个defer代码执行完毕后执行，以此类推。
```
    func processFile(filename: String) throws {
        if exists(filename) {
            let file = open(filename)
            defer {
                close(file)
            }
            while let line = try file.readline() {
                // Work with the file.
            }
            // close(file) is called here, at the end of the scope.
        }
    }
```